**assistant**:
> Below are selected log entries of past conversations, as part of an experimental AI memory system. T
**user**:
> I am trying to fill in zeros in an array with nans with the line:
> `weights = weights.where(~np.isnan(weights),0)`
> but I get the weird error: 
> Traceback (most recent call last):
>   File "<stdin>", line 1, in <module>
>   File "/Users/admin/opt/anaconda3/envs/ccenv3/lib/python3.10/site-packages/xarray/core/common.py", line 1284, in where
>     return ops.where_method(self, cond, other)
>   File "/Users/admin/opt/anaconda3/envs/ccenv3/lib/python3.10/site-packages/xarray/core/ops.py", line 176, in where_method
>     return apply_ufunc(
>   File "/Users/admin/opt/anaconda3/envs/ccenv3/lib/python3.10/site-packages/xarray/core/computation.py", line 1159, in apply_ufunc
>     return apply_dataarray_vfunc(
>   File "/Users/admin/opt/anaconda3/envs/ccenv3/lib/python3.10/site-packages/xarray/core/computation.py", line 270, in apply_dataarray_vfunc
>     args = deep_align(
>   File "/Users/admin/opt/anaconda3/envs/ccenv3/lib/python3.10/site-packages/xarray/core/alignment.py", line 436, in deep_align
>     aligned = align(
>   File "/Users/admin/opt/anaconda3/envs/ccenv3/lib/python3.10/site-packages/xarray/core/alignment.py", line 324, in align
>     raise ValueError(f"indexes along dimension {dim!r} are not equal")
> ValueError: indexes along dimension 'latitude' are not equal
> 
> This is an xarray matrix with latitude, so its referring to latitude isn't weird, but how can its dimensions be different from itself? Elsewhere this same line has worked.
**assistant**:
> The error you're encountering seems to stem from misalignment between the dimensions of `weights` and the condition you're applying with `np.isnan(weights)`. It suggests that the indexes along the 'latitude' dimension are not the same. Let's try a few steps to diagnose and fix the issue:
> 
> 1. **Check Alignment**: Ensure that the dimensions and coordinates are aligned. You can compare the coordinates of `weights` to check if `latitude` coordinates have the same values and order:
> 
>    ```python
>    print(weights['latitude'].values)
>    ```
> 
>    This will print the latitude values alongside their order, which should match what `np.isnan(weights)` provides.
> 
> 2. **Assign Coordinates Explicitly**: If you find differences, you might need to explicitly align the coordinates before using `where`. Sometimes using `.copy()` can inadvertently misalign coordinates, leading to such errors.
> 
> 3. **Ensure Consistent Coordinates**: If you've confirmed there are indeed differences, consider using the `.reindex()` or `.assign_coords()` methods to make sure `weights` and the condition align along the `latitude` dimension:
> 
>    ```python
>    common_latitudes = weights['latitude']
>    weights_aligned = weights.reindex(latitude=common_latitudes)
>    weights = weights_aligned.where(~np.isnan(weights_aligned), 0)
>    ```
> 
> 4. **Re-run Your Operation**: After aligning the coordinates, try running your `where` operation again.
> 
> Hopefully, this helps resolve the error. Let me know if the problem persists or if you need further assistance!
