**assistant**:
> Below are selected log entries of past conversations, as part of an experimental AI memory system. T
**user**:
> I'm trying to get a URL using pyppeteer, but I keep getting the error "Protocol Error (Page.navigate): Session closed. Most likely the page has been closed." What does this mean?
**assistant**:
> This error message in Pyppeteer typically indicates that the browser page instance you're attempting to navigate has been closed, either intentionally or due to some error. Here are some possible reasons and solutions:
> 
> 1. **Premature Browser/Page Closure**: Ensure that your script doesn't close the browser or the page before the navigation command is completed. Check for any explicit `await browser.close()` or `await page.close()` calls and ensure they are positioned appropriately after your navigation and tasks are done.
> 
> 2. **Code Execution Flow**: If you have asynchronous operations, make sure that the sequence of operations is correct and that the page is available when you attempt navigation. 
> 
> 3. **Unhandled Errors**: If an unhandled exception occurs, it might terminate the session, leading to this error. Wrap your navigation code in try-catch blocks to handle potential exceptions.
> 
> 4. **Timeouts**: By default, Pyppeteer waits for a certain amount of time for pages to navigate before throwing an error. If your pages take longer to load, consider increasing the timeout:
> 
>    ```python
>    await page.goto(url, {'timeout': 0})  # Setting timeout to zero disables it
>    ```
> 
> 5. **Resource Management**: Ensure you're managing resources correctly, not opening too many pages or sessions without closing them properly.
> 
> If none of these seem to address the problem, consider sharing more of your code so that we can look closer into its structure and flow to spot potential issues.
**user**:
> Can I check to see if the page object I'm using it still open?
**assistant**:
> Yes, you can check if a page object in Pyppeteer is still open by examining its `isClosed()` method. Hereâ€™s how you can do it:
> 
> ```python
> # Assuming you've already connected to the browser and created a page
> from pyppeteer import launch
> 
> async def check_page_status():
>     browser = await launch()
>     page = await browser.newPage()
> 
>     # Perform some operations
>     await page.goto('https://example.com')
> 
>     # Check if the page is open
>     if not page.isClosed():
>         print("The page is still open.")
>     else:
>         print("The page has been closed.")
> 
>     # Close the page
>     await page.close()
> 
>     # Check again
>     if not page.isClosed():
>         print("The page is still open.")
>     else:
>         print("The page has been closed.")
> 
>     await browser.close()
> 
> # To run this, you'll need an event loop like this:
> import asyncio
> asyncio.run(check_page_status())
> ```
> 
> ### Key Points
> 
> - **`page.isClosed()`**: This method returns `True` if the page has been closed and `False` otherwise.
> - **Resource Management**: Always ensure to close the page and browser appropriately to free system resources.
> - **Error Handling**: Consider adding try-except blocks around your code to handle any potential exceptions gracefully.
> 
> Let me know if you need more information on this!
**user**:
> After getting this error, I ran page.isClosed() and got "False".
**assistant**:
> If `page.isClosed()` returns `False`, it suggests that the page object is still open, but you're still encountering the "Protocol Error (Page.navigate)" issue. Here are some possibilities and troubleshooting steps you can take:
> 
> 1. **Session State**: Even if the page object is not closed, the underlying session might be compromised. This can happen if there was an issue with a previous command or a network error.
> 
> 2. **Race Conditions**: If you're executing multiple asynchronous commands, there might be a race condition causing the navigate command to fail. Ensure that commands are structured to complete in the expected order.
> 
> 3. **Browser Instance Status**: Check if the browser instance itself has closed or encountered an error. You can track this by listening to the browser's events (like `disconnected`).
> 
> 4. **Error Handling**: Add error handling around your navigation code to catch and log any other issues that might provide more context.
> 
>    ```python
>    try:
>        await page.goto('https://example.com')
>    except Exception as e:
>        print(f"Error navigating to URL: {e}")
>    ```
> 
> 5. **Network Conditions**: Sometimes network issues can lead to temporary failures. Ensure that your internet connection is stable and that there are no connectivity issues.
> 
> 6. **Re-creating the Page**: If the issue persists, consider creating a new page instance instead of reusing the existing one if it's been in use for a while with many operations. 
> 
> 7. **Debugging**: Use `page.on('error', ...)` and `page.on('pageerror', ...)` to log any errors that occur within the page context. This might give you more insights into what's happening.
> 
> Example of setting up error logging:
> 
> ```python
> page.on('error', lambda err: print(f'Page error: {err}'))
> page.on('pageerror', lambda err: print(f'Page script error: {err}'))
> ```
> 
> By adding these debugging steps, you should be able to narrow down the root cause of the issue. If the problem continues, sharing more of your code or context would help in diagnosing the issue further.
**user**:
> Here's what I see with my simple test:
> ```
> >>> page.isClosed()
> False
> >>> resp = await page.goto("https://ri.conicet.gov.ar/bitstream/handle/11336/59\
> 771/CONICET_Digital_Nro.d45cc6a3-a0b0-4fad-a131-1bb03a3a28d3_A.pdf?sequence=2&i\
> sAllowed=y")
> Traceback (most recent call last):
>                                     File "/Users/admin/opt/anaconda3/envs/aiiter/lib/python3.13/concurrent/futures/_base.py", line 456, in result
>                                                                      return self.__get_result()
>                           ~~~~~~~~~~~~~~~~~^^
>                                                File "/Users/admin/opt/anaconda3/envs/aiiter/lib/python3.13/concurrent/futures/_base.py", line 401, in __get_result
>       raise self._exception
>                              File "<python-input-7>", line 1, in <module>
>                                                                              resp = await page.goto("https://ri.conicet.gov.ar/bitstream/handle/11336/59771/CONICET_Digital_Nro.d45cc6a3-a0b0-4fad-a131-1bb03a3a28d3_A.pdf?sequence=2&isAllowed=y")
>               ^^^^^^^^^^^^^^^^^^^^^^^^^^^^^^^^^^^^^^^^^^^^^^^^^^^^^^^^^^^^^^^^^^^^^^^^^^^^^^^^^^^^^^^^^^^^^^^^^^^^^^^^^^^^^^^^^^^^^^^^^^^^^^^^^^^^^^^^^^^^^^^^^^^^^^^^^^^^^^^
>                File "/Users/admin/opt/anaconda3/envs/aiiter/lib/python3.13/site-packages/pyppeteer/page.py", line 830, in goto
>                                                   result = await self._navigate(url, referrer)
>                            ^^^^^^^^^^^^^^^^^^^^^^^^^^^^^^^^^^^
>                                                                 File "/Users/admin/opt/anaconda3/envs/aiiter/lib/python3.13/site-packages/pyppeteer/page.py", line 844, in _navigate
>                         response = await self._client.send('Page.navigate', {'url': url, 'referrer': referrer})
>                                                     ~~~~~~~~~~~~~~~~~^^^^^^^^^^^^^^^^^^^^^^^^^^^^^^^^^^^^^^^^^^^^^^^^^^^^^
>                                             File "/Users/admin/opt/anaconda3/envs/aiiter/lib/python3.13/site-packages/pyppeteer/connection.py", line 217, in send
>      raise NetworkError(
>                             ...<2 lines>...
>                                                )
>                                                 pyppeteer.errors.NetworkError: Protocol Error (Page.navigate): Session closed. Most likely the page has been closed.
>     >>> 
> ```
**assistant**:
> Thanks for providing the detailed output! Given that the error persists despite `page.isClosed()` returning `False`, letâ€™s dig deeper into potential causes and solutions:
> 
> ### Possible Causes and Solutions
> 
> 1. **Network Errors**: The URL may be causing the page to navigate to a resource that leads to network issues. Check if the URL is accessible directly from a browser. Sometimes, large files like PDFs can cause issues depending on the server's response time or network conditions.
> 
> 2. **Resource Type Handling**: Loading certain resource types might trigger a different type of handling in browsers. You can try adding some options to the `goto()` method to ignore specific errors:
> 
>    ```python
>    resp = await page.goto("https://ri.conicet.gov.ar/bitstream/handle/11336/59771/CONICET_Digital_Nro.d45cc6a3-a0b0-4fad-a131-1bb03a3a28d3_A.pdf?sequence=2&isAllowed=y", {
>        'waitUntil': 'networkidle0',  # Or 'domcontentloaded'
>        'timeout': 60000              # Set timeout longer if needed
>    })
>    ```
> 
> 3. **Retry Mechanism**: Implement a retry mechanism to handle transient errors. If the first attempt fails, wait a moment and try again:
> 
>    ```python
>    import asyncio
> 
>    async def safe_goto(page, url):
>        for _ in range(3):  # Try 3 times
>            try:
>                return await page.goto(url)
>            except Exception as e:
>                print(f"Navigation failed: {e}")
>                await asyncio.sleep(1)  # Wait a second before retrying
>        return None  # Return None if all attempts fail
> 
>    resp = await safe_goto(page, "https://ri.conicet.gov.ar/bitstream/handle/11336/59771/CONICET_Digital_Nro.d45cc6a3-a0b0-4fad-a131-1bb03a3a28d3_A.pdf?sequence=2&isAllowed=y")
>    ```
> 
> 4. **Check Event Listeners**: Ensure that there are no event listeners that might inadvertently close the page or browser. Review any code related to page events or browser session management.
> 
> 5. **Debugging Network Activity**: Use the Chrome DevTools Protocol to analyze network activities. You can listen for network requests to see if the request goes through or gets canceled:
> 
>    ```python
>    page.on('request', lambda request: print(f'Request: {request.url}'))
>    page.on('response', lambda response: print(f'Response: {response.status} for {response.url}'))
>    ```
> 
> 6. **Update Pyppeteer**: Ensure you're using the latest version of Pyppeteer. Sometimes, bugs get fixed in newer releases. You can update it via pip:
> 
>    ```bash
>    pip install -U pyppeteer
>    ```
> 
> If these suggestions don't resolve the issue, you might want to consider stripping down your test to the minimum code necessary to isolate the problem. Sometimes simplifying the code helps surface hidden issues. Let me know how it goes!
**user**:
> So, that URL does seem a bit flaky, but I'm trying another one and getting the same response. I've added the event handlers, but I don't see them acting:
> ```
> >>> page.on('request', lambda request: print(f'Request: {request.url}'))
> ... page.on('response', lambda response: print(f'Response: {response.status} for {response.url}'))
> ... 
> <function <lambda> at 0x112e49e40>
>                                   >>> resp = await page.goto("https://www.sciencedirect.com/science/article/pii/S0959378016300565", { 'waitUntil': 'networkidle0', 'tim
> Traceback (most recent call last):
>                                     File "/Users/admin/opt/anaconda3/envs/aiiter/lib/python3.13/concurrent/futures/_base.py", line 456, in result
>                                                                                                                                                      return self.__get_result()
>                    ~~~~~~~~~~~~~~~~~^^
>                                         File "/Users/admin/opt/anaconda3/envs/aiiter/lib/python3.13/concurrent/futures/_base.py", line 401, in __get_result
>                                                                                                                                                                raise self._exception
>                File "<python-input-18>", line 1, in <module>
>                                                                 resp = await page.goto("https://www.sciencedirect.com/science/article/pii/S0959378016300565", { 'waitUntil': 'networkidle0', 'timeout': 60000 })
>                                                     ^^^^^^^^^^^^^^^^^^^^^^^^^^^^^^^^^^^^^^^^^^^^^^^^^^^^^^^^^^^^^^^^^^^^^^^^^^^^^^^^^^^^^^^^^^^^^^^^^^^^^^^^^^^^^^^^^^^^^^^^^^^^^^^^^^^^^^^^^
>                         File "/Users/admin/opt/anaconda3/envs/aiiter/lib/python3.13/site-packages/pyppeteer/page.py", line 830, in goto
>                                                                                                                                            result = await self._navigate(url, referrer)
>                              ^^^^^^^^^^^^^^^^^^^^^^^^^^^^^^^^^^^
>                                                                   File "/Users/admin/opt/anaconda3/envs/aiiter/lib/python3.13/site-packages/pyppeteer/page.py", line 844, in _navigate
>                    response = await self._client.send('Page.navigate', {'url': url, 'referrer': referrer})
>                                                                                                                                ~~~~~~~~~~~~~~~~~^^^^^^^^^^^^^^^^^^^^^^^^^^^^^^^^^^^^^^^^^^^^^^^^^^^^^
>                                 File "/Users/admin/opt/anaconda3/envs/aiiter/lib/python3.13/site-packages/pyppeteer/connection.py", line 217, in send
>                                                                                                                                                          raise NetworkError(
>          ...<2 lines>...
>                             )
>                              pyppeteer.errors.NetworkError: Protocol Error (Page.navigate): Session closed. Most likely the page has been closed.
> ```
**assistant**:
> It seems youâ€™re encountering persistent issues when trying to navigate to the specified URLs, even with `page.isClosed()` returning `False`. Here are a few more troubleshooting steps to consider:
> 
> ### Debugging Steps
> 
> 1. **Check for Console Errors**: Add a handler for console messages to see if there are any JavaScript errors on the page that might be causing an issue:
> 
>    ```python
>    page.on('console', lambda msg: print(f'Console: {msg.text}'))
>    ```
> 
> 2. **Correctly Set Event Handlers**: Verify that your event handlers are set up correctly before calling `goto()`, to ensure they can capture the relevant events. Hereâ€™s a full setup with event listeners:
> 
>    ```python
>    async def test_navigation(page):
>        page.on('request', lambda request: print(f'Request: {request.url}'))
>        page.on('response', lambda response: print(f'Response: {response.status} for {response.url}'))
>        page.on('console', lambda msg: print(f'Console: {msg.text}'))
> 
>        # Try the URL
>        try:
>            resp = await page.goto("https://www.sciencedirect.com/science/article/pii/S0959378016300565", { 
>                'waitUntil': 'networkidle0', 
>                'timeout': 60000 
>            })
>            if resp is not None:
>                print(f"Response status: {resp.status}")
>            else:
>                print("No response received.")
>        except Exception as e:
>            print(f"Error during navigation: {e}")
> 
>    await test_navigation(page)
>    ```
> 
> 3. **Retry Logic**: Implementing retry logic may uncover intermittent issues. See if repeating the navigation after a brief pause helps:
> 
>    ```python
>    async def safe_goto(page, url):
>        for _ in range(3):
>            try:
>                return await page.goto(url, {'waitUntil': 'networkidle0', 'timeout': 60000})
>            except Exception as e:
>                print(f"Navigation failed: {e}")
>                await asyncio.sleep(1)  # Delay before retrying
>        return None
> 
>    resp = await safe_goto(page, "https://www.sciencedirect.com/science/article/pii/S0959378016300565")
>    ```
> 
> 4. **Change Wait Conditions**: Instead of waiting for `networkidle0`, try switching to `domcontentloaded` or `load` to see if those conditions work better:
> 
>    ```python
>    resp = await page.goto("https://www.sciencedirect.com/science/article/pii/S0959378016300565", { 
>        'waitUntil': 'domcontentloaded',  # or 'load'
>        'timeout': 60000 
>    })
>    ```
> 
> 5. **Environment and Dependencies**: Ensure Pyppeteer and its dependencies are up to date:
> 
>    ```bash
>    pip install -U pyppeteer
>    ```
> 
> 6. **Debugging Network Traffic**: Use a proxy or network tool like Fiddler or Wireshark to see if the requests go out and what responses theyâ€™re receiving.
> 
> ### Last Resort
> 
> If you continue experiencing errors, consider creating a minimal, reproducible example or testing with a different environment (e.g., a virtual machine or container). Sometimes configuration issues can be difficult to diagnose.
> 
> Let me know how things go with these steps!
**user**:
> The `test_navigation` and `safe_goto` and waitUntil=domcontentloaded all give the same result. pip says that pyppeteer is at its latest version.
> 
> Is it possible that sciencedirect.com is detecting that this is essentially a bot and refusing it?
**assistant**:
> Yes, it's entirely possible that the site (like ScienceDirect) is implementing measures to detect and block automated browsing tools, including Pyppeteer and other headless browsers. Many academic and commercial websites employ such techniques to prevent bots from accessing their content or scraping data.
> 
> ### Possible Triggering Mechanisms
> 
> 1. **User-Agent String**: Websites often check the User-Agent string to identify the browser type. Pyppeteer uses a default User-Agent that may signal bot-like behavior. You can try changing the User-Agent string to mimic a standard browser:
> 
>    ```python
>    await page.setUserAgent('Mozilla/5.0 (Windows NT 10.0; Win64; x64) AppleWebKit/537.36 (KHTML, like Gecko) Chrome/91.0.4472.124 Safari/537.36')
>    ```
> 
> 2. **JavaScript Challenges**: Some sites use JavaScript challenges to detect automated behavior. You can inspect the responses in a regular browser's DevTools to see if you hit such a protection mechanism.
> 
> 3. **Headless vs. Headed Mode**: Some sites may behave differently when accessed with headless browsers. Try running your Pyppeteer instance in headed mode:
> 
>    ```python
>    browser = await launch(headless=False)
>    ```
> 
> 4. **Cookies and Authentication**: If the site requires authentication or specific cookies, ensure you're handling those before making navigation calls.
> 
> 5. **Delay Between Actions**: Adding a delay between actions can sometimes help mimic human behavior:
> 
>    ```python
>    await asyncio.sleep(2)  # Adds a 2-second delay
>    ```
> 
> ### Example Code
> 
> Hereâ€™s how you could implement some of these suggestions in your existing code:
> 
> ```python
> async def test_navigation(page):
>     # Set User-Agent to mimic a regular browser
>     await page.setUserAgent('Mozilla/5.0 (Windows NT 10.0; Win64; x64) AppleWebKit/537.36 (KHTML, like Gecko) Chrome/91.0.4472.124 Safari/537.36')
> 
>     # Optionally you can try running in headed mode
>     # browser = await launch(headless=False)
> 
>     # Register event listeners
>     page.on('request', lambda request: print(f'Request: {request.url}'))
>     page.on('response', lambda response: print(f'Response: {response.status} for {response.url}'))
>     page.on('console', lambda msg: print(f'Console: {msg.text}'))
> 
>     # Add a delay if desired
>     await asyncio.sleep(2)
> 
>     # Try navigating to the URL
>     try:
>         resp = await page.goto("https://www.sciencedirect.com/science/article/pii/S0959378016300565", { 
>             'waitUntil': 'domcontentloaded', 
>             'timeout': 60000 
>         })
>         if resp is not None:
>             print(f"Response status: {resp.status}")
>         else:
>             print("No response received.")
>     except Exception as e:
>         print(f"Error during navigation: {e}")
> 
> await test_navigation(page)
> ```
> 
> ### If Still Blocked
> 
> If these adjustments don't work, you might consider:
> 
> - **Using a different library**: Tools like **Selenium** or **Playwright** have more built-in features for dealing with bot detection.
> - **Proxy Services**: Using a rotating proxy service can help if you've been IP-banned or rate-limited.
> 
> Monitoring the browser behavior closely during these tests can give you deeper insights into what might be going wrong. Let me know how it works out!
